<?xml version="1.0" ?>
<!-- =================================================================================== -->
<!-- |    This document was autogenerated by xacro from /catkin_ws/src/xArm_Lewansoul_ROS/xarm_description/urdf/xarm.urdf.xacro | -->
<!-- |    EDITING THIS FILE BY HAND IS NOT RECOMMENDED                                 | -->
<!-- =================================================================================== -->
<robot name="xarm">
    <material name="DarkGrey">
        <color rgba="0.3 0.3 0.3 1.0" />
    </material>
    <material name="Red">
        <color rgba="0.3 0.3 0.3 1.0" />
    </material>
    <material name="Black">
        <color rgba="0 0 0 1.0" />
    </material>
    <material name="Orange">
        <color rgba="0.0 0.15 0.7 1.0" />
    </material>
    <material name="Silver">
        <color rgba="1.0 1.0 1.0 1.0" />
    </material>
    <material name="Grey">
        <color rgba="0.7 0.7 0.7 1.0" />
    </material>
    <material name="Blue">
        <color rgba="0.0 0.0 0.8 1.0" />
    </material>
    <material name="HandGray">
        <color rgba="0.953 0.996 0.694 1.0" />
    </material>
    <material name="SickBlue">
        <color rgba="0.3058 0.5921 0.7294 1.0" />
    </material>
    <property name="M_PI" value="3.1415926535897931" />
    <link name="xarm_base_link">
        <visual>
            <origin rpy="0 0 0" xyz="0.0 0.0 0.0" />
            <geometry>
                <mesh filename="package://xarm_description/meshes/stls/base.stl" scale="1.0 1.0 1.0" />
            </geometry>
            <material name="Blue" />
        </visual>
        <collision>
            <origin rpy="0 0 0" xyz="0 0 0" />
            <geometry>
                <mesh filename="package://xarm_description/meshes/stls/base.stl" scale="1.0 1.0 1.0" />
            </geometry>
        </collision>
        <inertial>
            <mass value="0.1" />
            <origin xyz="0 0 0" rpy="0 0 0" />
            <inertia ixx="0.03" iyy="0.03" izz="0.03" ixy="0.0" ixz="0.0" iyz="0.0" />
        </inertial>
    </link>
    <joint name="xarm_6_joint" type="revolute">
        <origin rpy="0 0 0" xyz="0 0.0 0.03603" />
        <axis xyz="0 0 1" />
        <limit effort="1000" lower="-1.737238322" upper="1.79965407" velocity="1.0" />
        <!--safety_controller k_position="30" k_velocity="30" soft_lower_limit="-2.93215314335" soft_upper_limit="2.93215314335"/>
        <dynamics damping="1.0"/-->
        <parent link="xarm_base_link" />
        <child link="xarm_6_link" />
    </joint>
    <link name="xarm_6_link">
        <visual>
            <origin rpy="0 0 0" xyz="0.0 0.0 0.0" />
            <geometry>
                <mesh filename="package://xarm_description/meshes/stls/link6.stl" scale="1.0 1.0 1.0" />
            </geometry>
            <material name="DarkGrey" />
        </visual>
        <collision>
            <origin rpy="0 0 0" xyz="0.0 0.0 0.0" />
            <geometry>
                <mesh filename="package://xarm_description/meshes/stls/link6.stl" scale="1.0 1.0 1.0" />
            </geometry>
        </collision>
        <inertial>
            <mass value="0.1" />
            <inertia ixx="0.03" ixy="0.0" ixz="0.0" iyy="0.03" iyz="0.0" izz="0.03" />
            <origin xyz="0 0 0" rpy="0 0 0" />
        </inertial>
    </link>
    <joint name="xarm_5_joint" type="revolute">
        <origin rpy="0 0 0" xyz="0 -0.0022 0.03195" />
        <axis xyz="1 0 0" />
        <limit effort="1000" lower="-1.592023304" upper="1.86797401" velocity="1.0" />
        <!--safety_controller k_position="30" k_velocity="30" soft_lower_limit="-2.93215314335" soft_upper_limit="2.93215314335"/>
        <dynamics damping="1.0"/-->
        <parent link="xarm_6_link" />
        <child link="xarm_5_link" />
    </joint>
    <link name="xarm_5_link">
        <visual>
            <origin rpy="0 0 0" xyz="0.0 0.0 0.0" />
            <geometry>
                <mesh filename="package://xarm_description/meshes/stls/link5.stl" scale="1.0 1.0 1.0" />
            </geometry>
            <material name="Blue" />
        </visual>
        <collision>
            <origin rpy="0 0 0" xyz="0.0 0.0 0.0" />
            <geometry>
                <mesh filename="package://xarm_description/meshes/stls/link5.stl" scale="1.0 1.0 1.0" />
            </geometry>
        </collision>
        <inertial>
            <mass value="0.1" />
            <inertia ixx="0.03" ixy="0.0" ixz="0.0" iyy="0.03" iyz="0.0" izz="0.03" />
            <origin xyz="0 0 0" rpy="0 0 0" />
        </inertial>
    </link>
    <joint name="xarm_4_joint" type="revolute">
        <origin rpy="0 0 0" xyz="0 0.0 0.09765" />
        <axis xyz="1 0 0" />
        <limit effort="1000" lower="-1.910427965" upper="1.910427965" velocity="1.0" />
        <!--safety_controller k_position="30" k_velocity="30" soft_lower_limit="-2.93215314335" soft_upper_limit="2.93215314335"/>
        <dynamics damping="1.0"/-->
        <parent link="xarm_5_link" />
        <child link="xarm_4_link" />
    </joint>
    <link name="xarm_4_link">
        <visual>
            <origin rpy="0 0 0" xyz="0.0 0.0 0.0" />
            <geometry>
                <mesh filename="package://xarm_description/meshes/stls/link4.stl" scale="1.0 1.0 1.0" />
            </geometry>
            <material name="DarkGrey" />
        </visual>
        <collision>
            <origin rpy="0 0 0" xyz="0.0 0.0 0.0" />
            <geometry>
                <mesh filename="package://xarm_description/meshes/stls/link4.stl" scale="1.0 1.0 1.0" />
            </geometry>
        </collision>
        <inertial>
            <mass value="0.1" />
            <inertia ixx="0.03" ixy="0.0" ixz="0.0" iyy="0.03" iyz="0.0" izz="0.03" />
            <origin xyz="0 0 0" rpy="0 0 0" />
        </inertial>
    </link>
    <joint name="xarm_3_joint" type="revolute">
        <origin rpy="0 0 0" xyz="0 0.0 0.09825" />
        <axis xyz="1 0 0" />
        <limit effort="1000" lower="-1.740612146" upper="1.86797401" velocity="1.0" />
        <!--safety_controller k_position="30" k_velocity="30" soft_lower_limit="-2.93215314335" soft_upper_limit="2.93215314335"/>
        <dynamics damping="1.0"/-->
        <parent link="xarm_4_link" />
        <child link="xarm_3_link" />
    </joint>
    <link name="xarm_3_link">
        <visual>
            <origin rpy="0 0 0" xyz="0.0 0.0 0.0" />
            <geometry>
                <mesh filename="package://xarm_description/meshes/stls/link3.stl" scale="1.0 1.0 1.0" />
            </geometry>
            <material name="Blue" />
        </visual>
        <collision>
            <origin rpy="0 0 0" xyz="0.0 0.0 0.0" />
            <geometry>
                <mesh filename="package://xarm_description/meshes/stls/link3.stl" scale="1.0 1.0 1.0" />
            </geometry>
        </collision>
        <inertial>
            <mass value="0.1" />
            <inertia ixx="0.03" ixy="0.0" ixz="0.0" iyy="0.03" iyz="0.0" izz="0.03" />
            <origin xyz="0 0 0" rpy="0 0 0" />
        </inertial>
    </link>
    <joint name="xarm_2_joint" type="revolute">
        <origin rpy="0 0 0" xyz="0 -0.001205 0.05306" />
        <axis xyz="0 0 1" />
        <limit effort="1000" lower="-2.17494876" upper="1.63121157" velocity="1.0" />
        <!--safety_controller k_position="30" k_velocity="30" soft_lower_limit="-2.93215314335" soft_upper_limit="2.93215314335"/>
        <dynamics damping="1.0"/-->
        <parent link="xarm_3_link" />
        <child link="xarm_2_link" />
    </joint>
    <link name="xarm_2_link">
        <visual>
            <origin rpy="0 0 0" xyz="0.0 0.0 0.0" />
            <geometry>
                <mesh filename="package://xarm_description/meshes/stls/link2.stl" scale="1.0 1.0 1.0" />
            </geometry>
            <material name="DarkGrey" />
        </visual>
        <collision>
            <origin rpy="0 0 0" xyz="0.0 0.0 0.0" />
            <geometry>
                <mesh filename="package://xarm_description/meshes/stls/link2.stl" scale="1.0 1.0 1.0" />
            </geometry>
        </collision>
        <inertial>
            <mass value="0.1" />
            <inertia ixx="0.03" ixy="0.0" ixz="0.0" iyy="0.03" iyz="0.0" izz="0.03" />
            <origin xyz="0 0 0" rpy="0 0 0" />
        </inertial>
    </link>
    <joint name="xarm_servo_joint" type="fixed">
        <origin rpy="0 0 0" xyz="0 0 0.007548" />
        <axis xyz="0 0 1" />
        <limit effort="1000" lower="0.0" upper="1.0" velocity="1.0" />
        <parent link="xarm_2_link" />
        <child link="xarm_1_link" />
    </joint>
    <link name="xarm_1_link">
        <visual>
            <origin rpy="0 0 0" xyz="0.0 0.0 0.0" />
            <geometry>
                <mesh filename="package://xarm_description/meshes/stls/ID1_servo.stl" scale=".001 .001 .001" />
            </geometry>
            <material name="DarkGrey" />
        </visual>
        <collision>
            <origin rpy="0 0 0" xyz="0.0 0.0 0.0" />
            <geometry>
                <mesh filename="package://xarm_description/meshes/stls/ID1_servo.stl" scale=".001 .001 .001" />
            </geometry>
        </collision>
        <inertial>
            <mass value="0.1" />
            <inertia ixx="0.03" ixy="0.0" ixz="0.0" iyy="0.03" iyz="0.0" izz="0.03" />
            <origin xyz="0 0 0" rpy="0 0 0" />
        </inertial>
    </link>
    <!--material name="Gray">
    <color rgba="0.2 0.2 0.21 1.0"/-->
    <!-- gripper joint -->
    <!-- Finger 1 -->
    <joint name="xarm_1_joint" type="prismatic">
        <origin rpy="0 0 0" xyz="0 0 0.070" />
        <axis xyz="1 0 0" />
        <limit effort="30" lower="0" upper="1" velocity="0.5" />
        <parent link="xarm_1_link" />
        <child link="dummy_gripper_link" />
    </joint>
    <link name="dummy_gripper_link" />
    <joint name="xarm_tip1_joint" type="prismatic">
        <origin rpy="0 0 0" xyz="0 0 0.070" />
        <axis xyz="1 0 0" />
        <limit effort="30" lower="0" upper="1" velocity="0.5" />
        <parent link="xarm_1_link" />
        <child link="xarm_gripper_tip1" />
        <mimic joint="xarm_1_joint" multiplier="0.028" offset="0" />
    </joint>
    <link name="xarm_gripper_tip1">
        <inertial>
            <!-- TODO: This inertial field needs doesn't contain reliable data!! -->
            <mass value="0.01" />
            <origin xyz="0 0 0" rpy="0 0 0" />
            <inertia ixx="0.000001" ixy="0.0" ixz="0.0" iyy="0.000001" iyz="0.0" izz="0.000001" />
        </inertial>
        <visual>
            <origin rpy="1.570795 0 0" xyz="0 0.012 -.035" />
            <geometry>
                <mesh filename="package://xarm_description/meshes/stls/right_finger-90.stl" scale=".001 .001 .001" />
            </geometry>
            <material name="blue">
                <color rgba="0.3 0.5 0.9 1.0" />
            </material>
        </visual>
        <collision>
            <origin rpy="1.570795 0 0" xyz="0 0.012 -.035" />
            <geometry>
                <mesh filename="package://xarm_description/meshes/stls/right_finger-90.stl" scale=".001 .001 .001" />
            </geometry>
        </collision>
    </link>
    <!-- Finger 2 -->
    <!-- Note: currently static but should be a Mimic of Finger 1 -->
    <joint name="xarm_tip2_joint" type="prismatic">
        <origin rpy="0 0 0" xyz="0 0 0.070" />
        <axis xyz="1 0 0" />
        <limit effort="30" lower="-1" upper="0" velocity="0.5" />
        <parent link="xarm_1_link" />
        <child link="xarm_gripper_tip2" />
        <mimic joint="xarm_1_joint" multiplier="-0.028" offset="0" />
    </joint>
    <link name="xarm_gripper_tip2">
        <inertial>
            <!-- TODO: This inertial field needs doesn't contain reliable data!! -->
            <mass value="0.01" />
            <origin xyz="0 0 0" rpy="0 0 0" />
            <inertia ixx="0.000001" ixy="0.0" ixz="0.0" iyy="0.000001" iyz="0.0" izz="0.000001" />
        </inertial>
        <visual>
            <origin rpy="-1.570795 3.14159 0" xyz="0 0 -.035" />
            <geometry>
                <mesh filename="package://xarm_description/meshes/stls/right_finger-90.stl" scale=".001 .001 .001" />
            </geometry>
            <material name="blue">
                <color rgba="0.3 0.5 0.9 1.0" />
            </material>
        </visual>
        <collision>
            <origin rpy="-1.570795 3.14159 0" xyz="0 0 -.035" />
            <geometry>
                <mesh filename="package://xarm_description/meshes/stls/right_finger-90.stl" scale=".001 .001 .001" />
            </geometry>
        </collision>
    </link>
    <transmission name="trans_xarm_6_joint">
        <type>transmission_interface/SimpleTransmission</type>
        <joint name="xarm_6_joint">
            <hardwareInterface>hardware_interface/EffortJointInterface</hardwareInterface>
        </joint>
        <actuator name="xarm_6_joint_motor">
            <hardwareInterface>hardware_interface/EffortJointInterface</hardwareInterface>
            <mechanicalReduction>1</mechanicalReduction>
        </actuator>
    </transmission>
    <transmission name="trans_xarm_5_joint">
        <type>transmission_interface/SimpleTransmission</type>
        <joint name="xarm_5_joint">
            <hardwareInterface>hardware_interface/EffortJointInterface</hardwareInterface>
        </joint>
        <actuator name="xarm_5_joint_motor">
            <hardwareInterface>hardware_interface/EffortJointInterface</hardwareInterface>
            <mechanicalReduction>1</mechanicalReduction>
        </actuator>
    </transmission>
    <transmission name="trans_xarm_4_joint">
        <type>transmission_interface/SimpleTransmission</type>
        <joint name="xarm_4_joint">
            <hardwareInterface>hardware_interface/EffortJointInterface</hardwareInterface>
        </joint>
        <actuator name="xarm_4_joint_motor">
            <hardwareInterface>hardware_interface/EffortJointInterface</hardwareInterface>
            <mechanicalReduction>1</mechanicalReduction>
        </actuator>
    </transmission>
    <transmission name="trans_xarm_3_joint">
        <type>transmission_interface/SimpleTransmission</type>
        <joint name="xarm_3_joint">
            <hardwareInterface>hardware_interface/EffortJointInterface</hardwareInterface>
        </joint>
        <actuator name="xarm_3_joint_motor">
            <hardwareInterface>hardware_interface/EffortJointInterface</hardwareInterface>
            <mechanicalReduction>1</mechanicalReduction>
        </actuator>
    </transmission>
    <transmission name="trans_xarm_2_joint">
        <type>transmission_interface/SimpleTransmission</type>
        <joint name="xarm_2_joint">
            <hardwareInterface>hardware_interface/EffortJointInterface</hardwareInterface>
        </joint>
        <actuator name="xarm_2_joint_motor">
            <hardwareInterface>hardware_interface/EffortJointInterface</hardwareInterface>
            <mechanicalReduction>1</mechanicalReduction>
        </actuator>
    </transmission>
    <gazebo>
        <plugin filename="libgazebo_ros_control.so" name="gazebo_ros_control">
            <robotNamespace>/</robotNamespace>
        </plugin>
    </gazebo>
    <transmission name="trans_xarm_1_joint">
        <type>transmission_interface/SimpleTransmission</type>
        <joint name="xarm_1_joint">
            <hardwareInterface>hardware_interface/EffortJointInterface</hardwareInterface>
        </joint>
        <actuator name="xarm_1_joint_motor">
            <hardwareInterface>hardware_interface/EffortJointInterface</hardwareInterface>
            <mechanicalReduction>1</mechanicalReduction>
        </actuator>
    </transmission>
    <transmission name="trans_xarm_tip1_joint">
        <type>transmission_interface/SimpleTransmission</type>
        <joint name="xarm_tip1_joint">
            <hardwareInterface>hardware_interface/EffortJointInterface</hardwareInterface>
        </joint>
        <actuator name="xarm_tip1_joint_motor">
            <hardwareInterface>hardware_interface/EffortJointInterface</hardwareInterface>
            <mechanicalReduction>1</mechanicalReduction>
        </actuator>
    </transmission>
    <transmission name="trans_xarm_tip2_joint">
        <type>transmission_interface/SimpleTransmission</type>
        <joint name="xarm_tip2_joint">
            <hardwareInterface>hardware_interface/EffortJointInterface</hardwareInterface>
        </joint>
        <actuator name="xarm_tip2_joint_motor">
            <hardwareInterface>hardware_interface/EffortJointInterface</hardwareInterface>
            <mechanicalReduction>1</mechanicalReduction>
        </actuator>
    </transmission>
</robot>

